<?xml version="1.0"?>
<sdf version="1.9">
  <model name="tiago">
    <self_collide>false</self_collide>
    <allow_auto_disable>false</allow_auto_disable>

    <link name="base_link">
      <inertial>
        <pose>0 0 0.22 0 0 0</pose>
        <mass>22.0</mass>
        <inertia>
          <ixx>0.65</ixx>
          <iyy>0.65</iyy>
          <izz>0.70</izz>
          <ixy>0</ixy>
          <ixz>0</ixz>
          <iyz>0</iyz>
        </inertia>
      </inertial>
      <visual name="base_link_visual">
        <pose>0 0 0.22 0 0 0</pose>
        <geometry>
          <cylinder>
            <radius>0.20</radius>
            <length>0.20</length>
          </cylinder>
        </geometry>
        <material>
          <ambient>0.15 0.15 0.15 1</ambient>
          <diffuse>0.15 0.15 0.15 1</diffuse>
        </material>
      </visual>
      <collision name="base_link_collision">
        <pose>0 0 0.22 0 0 0</pose>
        <geometry>
          <cylinder>
            <radius>0.22</radius>
            <length>0.20</length>
          </cylinder>
        </geometry>
      </collision>
    </link>

    <link name="base_footprint">
      <pose relative_to="base_footprint_joint">0 0 0 0 0 0</pose>
    </link>

    <link name="left_wheel_link">
      <pose relative_to="left_wheel_joint">0 0 0 0 0 0</pose>
      <inertial>
        <mass>1.0</mass>
        <inertia>
          <ixx>0.003</ixx>
          <iyy>0.005</iyy>
          <izz>0.003</izz>
          <ixy>0</ixy>
          <ixz>0</ixz>
          <iyz>0</iyz>
        </inertia>
      </inertial>
      <visual name="left_wheel_visual">
        <geometry>
          <cylinder>
            <radius>0.10</radius>
            <length>0.05</length>
          </cylinder>
        </geometry>
        <material>
          <ambient>0.12 0.12 0.12 1</ambient>
          <diffuse>0.12 0.12 0.12 1</diffuse>
        </material>
      </visual>
      <collision name="left_wheel_collision">
        <geometry>
          <cylinder>
            <radius>0.10</radius>
            <length>0.05</length>
          </cylinder>
        </geometry>
        <surface>
          <friction>
            <ode>
              <mu>2.5</mu>
              <mu2>2.5</mu2>
            </ode>
          </friction>
        </surface>
      </collision>
    </link>

    <link name="right_wheel_link">
      <pose relative_to="right_wheel_joint">0 0 0 0 0 0</pose>
      <inertial>
        <mass>1.0</mass>
        <inertia>
          <ixx>0.003</ixx>
          <iyy>0.005</iyy>
          <izz>0.003</izz>
          <ixy>0</ixy>
          <ixz>0</ixz>
          <iyz>0</iyz>
        </inertia>
      </inertial>
      <visual name="right_wheel_visual">
        <geometry>
          <cylinder>
            <radius>0.10</radius>
            <length>0.05</length>
          </cylinder>
        </geometry>
        <material>
          <ambient>0.12 0.12 0.12 1</ambient>
          <diffuse>0.12 0.12 0.12 1</diffuse>
        </material>
      </visual>
      <collision name="right_wheel_collision">
        <geometry>
          <cylinder>
            <radius>0.10</radius>
            <length>0.05</length>
          </cylinder>
        </geometry>
        <surface>
          <friction>
            <ode>
              <mu>2.5</mu>
              <mu2>2.5</mu2>
            </ode>
          </friction>
        </surface>
      </collision>
    </link>

    <link name="caster_front_link">
      <pose relative_to="caster_front_joint">0 0 0 0 0 0</pose>
      <inertial>
        <mass>0.25</mass>
        <inertia>
          <ixx>0.0002</ixx>
          <iyy>0.0002</iyy>
          <izz>0.0002</izz>
          <ixy>0</ixy>
          <ixz>0</ixz>
          <iyz>0</iyz>
        </inertia>
      </inertial>
      <visual name="caster_front_visual">
        <geometry>
          <sphere>
            <radius>0.03</radius>
          </sphere>
        </geometry>
      </visual>
      <collision name="caster_front_collision">
        <geometry>
          <sphere>
            <radius>0.03</radius>
          </sphere>
        </geometry>
        <surface>
          <friction>
            <ode>
              <mu>0.01</mu>
              <mu2>0.01</mu2>
            </ode>
          </friction>
        </surface>
      </collision>
    </link>

    <link name="caster_rear_link">
      <pose relative_to="caster_rear_joint">0 0 0 0 0 0</pose>
      <inertial>
        <mass>0.25</mass>
        <inertia>
          <ixx>0.0002</ixx>
          <iyy>0.0002</iyy>
          <izz>0.0002</izz>
          <ixy>0</ixy>
          <ixz>0</ixz>
          <iyz>0</iyz>
        </inertia>
      </inertial>
      <visual name="caster_rear_visual">
        <geometry>
          <sphere>
            <radius>0.03</radius>
          </sphere>
        </geometry>
      </visual>
      <collision name="caster_rear_collision">
        <geometry>
          <sphere>
            <radius>0.03</radius>
          </sphere>
        </geometry>
        <surface>
          <friction>
            <ode>
              <mu>0.01</mu>
              <mu2>0.01</mu2>
            </ode>
          </friction>
        </surface>
      </collision>
    </link>

    <link name="torso_fixed_link">
      <pose relative_to="base_to_torso_fixed">0 0 0 0 0 0</pose>
      <inertial>
        <pose>0.02435 -0.00464 0.159 0 0 0</pose>
        <mass>14.0136</mass>
        <inertia>
          <ixx>0.383411</ixx>
          <iyy>0.405773</iyy>
          <izz>0.076998</izz>
          <ixy>0.000364</ixy>
          <ixz>-0.024389</ixz>
          <iyz>-0.000782</iyz>
        </inertia>
      </inertial>
      <visual name="torso_fixed_link_visual">
        <geometry>
          <mesh>
            <uri>model://tiago/meshes/torso/torso_fix.stl</uri>
          </mesh>
        </geometry>
      </visual>
      <collision name="torso_fixed_link_collision">
        <geometry>
          <mesh>
            <uri>model://tiago/meshes/torso/torso_fix.stl</uri>
          </mesh>
        </geometry>
      </collision>
    </link>

    <link name="torso_lift_link">
      <pose relative_to="torso_lift_joint">0 0 0 0 0 0</pose>
      <inertial>
        <pose>0.04361 -0.00116 -0.17334 0 0 0</pose>
        <mass>6.93198</mass>
        <inertia>
          <ixx>0.24487</ixx>
          <iyy>0.249269</iyy>
          <izz>0.090395</izz>
          <ixy>-0.001456</ixy>
          <ixz>-0.009742</ixz>
          <iyz>0.008281</iyz>
        </inertia>
      </inertial>
      <visual name="torso_lift_link_visual">
        <geometry>
          <mesh>
            <uri>model://tiago/meshes/torso/torso_lift_with_arm.stl</uri>
          </mesh>
        </geometry>
      </visual>
      <collision name="torso_lift_link_collision">
        <geometry>
          <mesh>
            <uri>model://tiago/meshes/torso/torso_lift_with_arm.stl</uri>
          </mesh>
        </geometry>
      </collision>
    </link>

    <link name="arm_1_link">
      <pose relative_to="arm_1_joint">0 0 0 0 0 0</pose>
      <inertial>
        <pose>0.061191 -0.022397 -0.012835 0 0 0</pose>
        <mass>1.563428</mass>
        <inertia>
          <ixx>0.002471</ixx>
          <iyy>0.006132</iyy>
          <izz>0.006704</izz>
          <ixy>0.001809</ixy>
          <ixz>-0.001202</ixz>
          <iyz>0.000494</iyz>
        </inertia>
      </inertial>
      <visual name="arm_1_link_visual">
        <geometry>
          <mesh>
            <uri>model://tiago/meshes/arm/arm_1.stl</uri>
          </mesh>
        </geometry>
      </visual>
      <collision name="arm_1_link_collision">
        <geometry>
          <mesh>
            <uri>model://tiago/meshes/arm/arm_1.stl</uri>
          </mesh>
        </geometry>
      </collision>
    </link>

    <link name="arm_2_link">
      <pose relative_to="arm_2_joint">0 0 0 0 0 0</pose>
      <inertial>
        <pose>0.030432 0.000229 -0.005942 0 0 0</pose>
        <mass>1.800397</mass>
        <inertia>
          <ixx>0.001809</ixx>
          <iyy>0.004333</iyy>
          <izz>0.004341</izz>
          <ixy>0.000015</ixy>
          <ixz>0.000254</ixz>
          <iyz>0.000014</iyz>
        </inertia>
      </inertial>
      <visual name="arm_2_link_visual">
        <geometry>
          <mesh>
            <uri>model://tiago/meshes/arm/arm_2.stl</uri>
          </mesh>
        </geometry>
      </visual>
      <collision name="arm_2_link_collision">
        <geometry>
          <mesh>
            <uri>model://tiago/meshes/arm/arm_2.stl</uri>
          </mesh>
        </geometry>
      </collision>
    </link>

    <link name="arm_3_link">
      <pose relative_to="arm_3_joint">0 0 0 0 0 0</pose>
      <inertial>
        <pose>0.007418 -0.004361 -0.134194 0 0 0</pose>
        <mass>1.8</mass>
        <inertia>
          <ixx>0.019541</ixx>
          <iyy>0.019936</iyy>
          <izz>0.002864</izz>
          <ixy>0.000105</ixy>
          <ixz>-0.001717</ixz>
          <iyz>0.000852</iyz>
        </inertia>
      </inertial>
      <visual name="arm_3_link_visual">
        <geometry>
          <mesh>
            <uri>model://tiago/meshes/arm/arm_3.stl</uri>
          </mesh>
        </geometry>
      </visual>
      <collision name="arm_3_link_collision">
        <geometry>
          <mesh>
            <uri>model://tiago/meshes/arm/arm_3.stl</uri>
          </mesh>
        </geometry>
      </collision>
    </link>

    <link name="arm_4_link">
      <pose relative_to="arm_4_joint">0 0 0 0 0 0</pose>
      <inertial>
        <pose>-0.095658 0.014666 0.018133 0 0 0</pose>
        <mass>1.432697</mass>
        <inertia>
          <ixx>0.002040</ixx>
          <iyy>0.008424</iyy>
          <izz>0.008686</izz>
          <ixy>0.000725</ixy>
          <ixz>-0.001150</ixz>
          <iyz>-0.000204</iyz>
        </inertia>
      </inertial>
      <visual name="arm_4_link_visual">
        <geometry>
          <mesh>
            <uri>model://tiago/meshes/arm/arm_4.stl</uri>
          </mesh>
        </geometry>
      </visual>
      <collision name="arm_4_link_collision">
        <geometry>
          <mesh>
            <uri>model://tiago/meshes/arm/arm_4.stl</uri>
          </mesh>
        </geometry>
      </collision>
    </link>

    <link name="arm_5_link">
      <pose relative_to="arm_5_joint">0 0 0 0 0 0</pose>
      <inertial>
        <pose>0.001078 -0.000151 -0.077173 0 0 0</pose>
        <mass>1.655819</mass>
        <inertia>
          <ixx>0.006138</ixx>
          <iyy>0.005640</iyy>
          <izz>0.001797</izz>
          <ixy>-0.000004</ixy>
          <ixz>0.000156</ixz>
          <iyz>0.000022</iyz>
        </inertia>
      </inertial>
      <visual name="arm_5_link_visual">
        <geometry>
          <mesh>
            <uri>model://tiago/meshes/arm/arm_5-wrist-2010.stl</uri>
          </mesh>
        </geometry>
      </visual>
      <collision name="arm_5_link_collision">
        <geometry>
          <mesh>
            <uri>model://tiago/meshes/arm/arm_5-wrist-2010.stl</uri>
          </mesh>
        </geometry>
      </collision>
    </link>

    <link name="arm_6_link">
      <pose relative_to="arm_6_joint">0 0 0 0 0 0</pose>
      <inertial>
        <pose>-0.000153 -0.003122 0.000183 0 0 0</pose>
        <mass>0.370063</mass>
        <inertia>
          <ixx>0.000215</ixx>
          <iyy>0.000170</iyy>
          <izz>0.000174</izz>
          <ixy>0</ixy>
          <ixz>0</ixz>
          <iyz>0.000002</iyz>
        </inertia>
      </inertial>
      <visual name="arm_6_link_visual">
        <geometry>
          <mesh>
            <uri>model://tiago/meshes/arm/arm_6-wrist-2010.stl</uri>
          </mesh>
        </geometry>
      </visual>
      <collision name="arm_6_link_collision">
        <geometry>
          <mesh>
            <uri>model://tiago/meshes/arm/arm_6-wrist-2010.stl</uri>
          </mesh>
        </geometry>
      </collision>
    </link>

    <link name="arm_7_link">
      <pose relative_to="arm_7_joint">0 0 0 0 0 0</pose>
      <inertial>
        <pose>0.000010 -0.000003 -0.007774 0 0 0</pose>
        <mass>0.234252</mass>
        <inertia>
          <ixx>0.000142</ixx>
          <iyy>0.000113</iyy>
          <izz>0.000052</izz>
          <ixy>0</ixy>
          <ixz>0</ixz>
          <iyz>0</iyz>
        </inertia>
      </inertial>
      <visual name="arm_7_link_visual">
        <pose>0 0 0.02 0 0 0</pose>
        <geometry>
          <cylinder>
            <radius>0.02</radius>
            <length>0.04</length>
          </cylinder>
        </geometry>
      </visual>
      <collision name="arm_7_link_collision">
        <pose>0 0 0.02 0 0 0</pose>
        <geometry>
          <cylinder>
            <radius>0.02</radius>
            <length>0.04</length>
          </cylinder>
        </geometry>
      </collision>
    </link>

    <link name="arm_tool_link">
      <pose relative_to="arm_tool_joint">0 0 0 0 0 0</pose>
      <inertial>
        <mass>0.1</mass>
        <inertia>
          <ixx>0.0001</ixx>
          <iyy>0.0001</iyy>
          <izz>0.0001</izz>
          <ixy>0</ixy>
          <ixz>0</ixz>
          <iyz>0</iyz>
        </inertia>
      </inertial>
      <visual name="arm_tool_link_visual">
        <pose>0.001 0 0 0 1.57079632679 0</pose>
        <geometry>
          <cylinder>
            <radius>0.005</radius>
            <length>0.005</length>
          </cylinder>
        </geometry>
      </visual>
      <collision name="arm_tool_link_collision">
        <pose>0.001 0 0 0 1.57079632679 0</pose>
        <geometry>
          <cylinder>
            <radius>0.005</radius>
            <length>0.005</length>
          </cylinder>
        </geometry>
      </collision>
    </link>

    <link name="head_1_link">
      <pose relative_to="head_1_joint">0 0 0 0 0 0</pose>
      <inertial>
        <pose>-0.00508 0.00237 0.07229 0 0 0</pose>
        <mass>0.62220</mass>
        <inertia>
          <ixx>0.001192</ixx>
          <iyy>0.001402</iyy>
          <izz>0.000889</izz>
          <ixy>-0.000007</ixy>
          <ixz>0.000096</ixz>
          <iyz>0.000004</iyz>
        </inertia>
      </inertial>
      <visual name="head_1_link_visual">
        <geometry>
          <mesh>
            <uri>model://tiago/meshes/head/head_1.stl</uri>
          </mesh>
        </geometry>
      </visual>
      <collision name="head_1_link_collision">
        <geometry>
          <mesh>
            <uri>model://tiago/meshes/head/head_1.stl</uri>
          </mesh>
        </geometry>
      </collision>
    </link>

    <link name="head_2_link">
      <pose relative_to="head_2_joint">0 0 0 0 0 0</pose>
      <inertial>
        <pose>0.04700 0.05542 0.00022 0 0 0</pose>
        <mass>0.66123</mass>
        <inertia>
          <ixx>0.004620</ixx>
          <iyy>0.004861</iyy>
          <izz>0.003132</izz>
          <ixy>0.000689</ixy>
          <ixz>0.000006</ixz>
          <iyz>0.000006</iyz>
        </inertia>
      </inertial>
      <visual name="head_2_link_visual">
        <geometry>
          <mesh>
            <uri>model://tiago/meshes/head/head_2.stl</uri>
          </mesh>
        </geometry>
      </visual>
      <collision name="head_2_link_collision">
        <geometry>
          <mesh>
            <uri>model://tiago/meshes/head/head_2.stl</uri>
          </mesh>
        </geometry>
      </collision>
    </link>

    <joint name="base_footprint_joint" type="fixed">
      <parent>base_link</parent>
      <child>base_footprint</child>
      <pose relative_to="base_link">0 0 0 0 0 0</pose>
    </joint>

    <joint name="left_wheel_joint" type="revolute">
      <parent>base_link</parent>
      <child>left_wheel_link</child>
      <pose relative_to="base_link">0 0.23 0.10 -1.57079632679 0 0</pose>
      <axis>
        <xyz>0 0 1</xyz>
        <limit>
          <lower>-1e16</lower>
          <upper>1e16</upper>
          <effort>40</effort>
          <velocity>30</velocity>
        </limit>
        <dynamics>
          <damping>0.2</damping>
          <friction>0.05</friction>
        </dynamics>
      </axis>
    </joint>

    <joint name="right_wheel_joint" type="revolute">
      <parent>base_link</parent>
      <child>right_wheel_link</child>
      <pose relative_to="base_link">0 -0.23 0.10 -1.57079632679 0 0</pose>
      <axis>
        <xyz>0 0 1</xyz>
        <limit>
          <lower>-1e16</lower>
          <upper>1e16</upper>
          <effort>40</effort>
          <velocity>30</velocity>
        </limit>
        <dynamics>
          <damping>0.2</damping>
          <friction>0.05</friction>
        </dynamics>
      </axis>
    </joint>

    <joint name="caster_front_joint" type="ball">
      <parent>base_link</parent>
      <child>caster_front_link</child>
      <pose relative_to="base_link">0.18 0 0.03 0 0 0</pose>
    </joint>

    <joint name="caster_rear_joint" type="ball">
      <parent>base_link</parent>
      <child>caster_rear_link</child>
      <pose relative_to="base_link">-0.18 0 0.03 0 0 0</pose>
    </joint>

    <joint name="base_to_torso_fixed" type="fixed">
      <parent>base_link</parent>
      <child>torso_fixed_link</child>
      <pose relative_to="base_link">-0.062 0 0.193 0 0 0</pose>
    </joint>

    <joint name="torso_lift_joint" type="prismatic">
      <parent>torso_fixed_link</parent>
      <child>torso_lift_link</child>
      <pose relative_to="torso_fixed_link">0 0 0.597 0 0 0</pose>
      <axis>
        <xyz>0 0 1</xyz>
        <limit>
          <lower>0.0</lower>
          <upper>0.35</upper>
          <effort>2000.0</effort>
          <velocity>0.07</velocity>
        </limit>
        <dynamics>
          <damping>1500.0</damping>
          <friction>10.0</friction>
        </dynamics>
      </axis>
    </joint>

    <joint name="arm_1_joint" type="revolute">
      <parent>torso_lift_link</parent>
      <child>arm_1_link</child>
      <pose relative_to="torso_lift_link">0.15505 0.014 -0.151 0 0 -1.57079632679</pose>
      <axis>
        <xyz>0 0 1</xyz>
        <limit>
          <lower>0.0</lower>
          <upper>2.74889357189</upper>
          <effort>80.0</effort>
          <velocity>1.95</velocity>
        </limit>
        <dynamics>
          <damping>18.0</damping>
          <friction>0.4</friction>
        </dynamics>
      </axis>
    </joint>

    <joint name="arm_2_joint" type="revolute">
      <parent>arm_1_link</parent>
      <child>arm_2_link</child>
      <pose relative_to="arm_1_link">0.125 0.0195 -0.031 1.57079632679 0 0</pose>
      <axis>
        <xyz>0 0 1</xyz>
        <limit>
          <lower>-1.57079632679</lower>
          <upper>1.0908307825</upper>
          <effort>80.0</effort>
          <velocity>1.95</velocity>
        </limit>
        <dynamics>
          <damping>18.0</damping>
          <friction>0.4</friction>
        </dynamics>
      </axis>
    </joint>

    <joint name="arm_3_joint" type="revolute">
      <parent>arm_2_link</parent>
      <child>arm_3_link</child>
      <pose relative_to="arm_2_link">0.0895 0 -0.0015 -1.57079632679 0 1.57079632679</pose>
      <axis>
        <xyz>0 0 1</xyz>
        <limit>
          <lower>-3.53429173529</lower>
          <upper>1.57079632679</upper>
          <effort>55.0</effort>
          <velocity>2.35</velocity>
        </limit>
        <dynamics>
          <damping>18.0</damping>
          <friction>0.4</friction>
        </dynamics>
      </axis>
    </joint>

    <joint name="arm_4_joint" type="revolute">
      <parent>arm_3_link</parent>
      <child>arm_4_link</child>
      <pose relative_to="arm_3_link">-0.02 -0.027 -0.222 -1.57079632679 -1.57079632679 0</pose>
      <axis>
        <xyz>0 0 1</xyz>
        <limit>
          <lower>-0.3926990817</lower>
          <upper>2.35619449019</upper>
          <effort>26.0</effort>
          <velocity>2.35</velocity>
        </limit>
        <dynamics>
          <damping>30.0</damping>
          <friction>1.0</friction>
        </dynamics>
      </axis>
    </joint>

    <joint name="arm_5_joint" type="revolute">
      <parent>arm_4_link</parent>
      <child>arm_5_link</child>
      <pose relative_to="arm_4_link">-0.162 0.02 0.027 1.57079632679 -1.57079632679 -1.57079632679</pose>
      <axis>
        <xyz>0 0 1</xyz>
        <limit>
          <lower>-2.09439510239</lower>
          <upper>2.09439510239</upper>
          <effort>3.0</effort>
          <velocity>1.95</velocity>
        </limit>
        <dynamics>
          <damping>2.0</damping>
          <friction>0.5</friction>
        </dynamics>
      </axis>
    </joint>

    <joint name="arm_6_joint" type="revolute">
      <parent>arm_5_link</parent>
      <child>arm_6_link</child>
      <pose relative_to="arm_5_link">0 0 0.15 0 -1.57079632679 -1.57079632679</pose>
      <axis>
        <xyz>0 0 1</xyz>
        <limit>
          <lower>-1.41371669412</lower>
          <upper>1.41371669412</upper>
          <effort>6.6</effort>
          <velocity>1.76</velocity>
        </limit>
        <dynamics>
          <damping>2.0</damping>
          <friction>0.5</friction>
        </dynamics>
      </axis>
    </joint>

    <joint name="arm_7_joint" type="revolute">
      <parent>arm_6_link</parent>
      <child>arm_7_link</child>
      <pose relative_to="arm_6_link">0 0 0 1.57079632679 0 1.57079632679</pose>
      <axis>
        <xyz>0 0 1</xyz>
        <limit>
          <lower>-2.09439510239</lower>
          <upper>2.09439510239</upper>
          <effort>6.6</effort>
          <velocity>1.76</velocity>
        </limit>
        <dynamics>
          <damping>2.0</damping>
          <friction>0.5</friction>
        </dynamics>
      </axis>
    </joint>

    <joint name="arm_tool_joint" type="fixed">
      <parent>arm_7_link</parent>
      <child>arm_tool_link</child>
      <pose relative_to="arm_7_link">0 0 0.046 1.57079632679 -1.57079632679 3.14159265359</pose>
    </joint>

    <joint name="head_1_joint" type="revolute">
      <parent>torso_lift_link</parent>
      <child>head_1_link</child>
      <pose relative_to="torso_lift_link">0.182 0 0 0 0 0</pose>
      <axis>
        <xyz>0 0 1</xyz>
        <limit>
          <lower>-1.30899693899</lower>
          <upper>1.30899693899</upper>
          <effort>5.197</effort>
          <velocity>3.0</velocity>
        </limit>
        <dynamics>
          <damping>1.0</damping>
          <friction>0.1</friction>
        </dynamics>
      </axis>
    </joint>

    <joint name="head_2_joint" type="revolute">
      <parent>head_1_link</parent>
      <child>head_2_link</child>
      <pose relative_to="head_1_link">0.005 0 0.098 1.57079632679 0 0</pose>
      <axis>
        <xyz>0 0 1</xyz>
        <limit>
          <lower>-1.0471975512</lower>
          <upper>0.7853981634</upper>
          <effort>2.77</effort>
          <velocity>3.0</velocity>
        </limit>
        <dynamics>
          <damping>1.0</damping>
          <friction>0.1</friction>
        </dynamics>
      </axis>
    </joint>

    <plugin
      filename="gz-sim-diff-drive-system"
      name="gz::sim::systems::DiffDrive">
      <left_joint>left_wheel_joint</left_joint>
      <right_joint>right_wheel_joint</right_joint>
      <wheel_separation>0.46</wheel_separation>
      <wheel_radius>0.10</wheel_radius>
      <wheel_torque>120</wheel_torque>
      <max_linear_acceleration>1.0</max_linear_acceleration>
      <topic>cmd_vel</topic>
      <odom_topic>odom</odom_topic>
      <tf_topic>tf</tf_topic>
      <frame_id>odom</frame_id>
      <child_frame_id>base_footprint</child_frame_id>
      <odom_publisher_frequency>50</odom_publisher_frequency>
    </plugin>

    <plugin
      filename="gz-sim-joint-state-publisher-system"
      name="gz::sim::systems::JointStatePublisher">
      <joint_name>left_wheel_joint</joint_name>
      <joint_name>right_wheel_joint</joint_name>
      <joint_name>torso_lift_joint</joint_name>
      <joint_name>arm_1_joint</joint_name>
      <joint_name>arm_2_joint</joint_name>
      <joint_name>arm_3_joint</joint_name>
      <joint_name>arm_4_joint</joint_name>
      <joint_name>arm_5_joint</joint_name>
      <joint_name>arm_6_joint</joint_name>
      <joint_name>arm_7_joint</joint_name>
      <joint_name>head_1_joint</joint_name>
      <joint_name>head_2_joint</joint_name>
    </plugin>

    <plugin
      filename="gz-sim-joint-trajectory-controller-system"
      name="gz::sim::systems::JointTrajectoryController">
      <joint_name>torso_lift_joint</joint_name>
      <initial_position>0.05</initial_position>
      <position_p_gain>800.0</position_p_gain>
      <position_i_gain>0.8</position_i_gain>
      <position_d_gain>120.0</position_d_gain>
      <position_i_min>-2.0</position_i_min>
      <position_i_max>2.0</position_i_max>
      <position_cmd_min>-2500.0</position_cmd_min>
      <position_cmd_max>2500.0</position_cmd_max>

      <joint_name>arm_1_joint</joint_name>
      <initial_position>0.0</initial_position>
      <position_p_gain>140.0</position_p_gain>
      <position_i_gain>0.10</position_i_gain>
      <position_d_gain>22.0</position_d_gain>
      <position_i_min>-1.5</position_i_min>
      <position_i_max>1.5</position_i_max>
      <position_cmd_min>-240.0</position_cmd_min>
      <position_cmd_max>240.0</position_cmd_max>

      <joint_name>arm_2_joint</joint_name>
      <initial_position>0.0</initial_position>
      <position_p_gain>140.0</position_p_gain>
      <position_i_gain>0.10</position_i_gain>
      <position_d_gain>22.0</position_d_gain>
      <position_i_min>-1.5</position_i_min>
      <position_i_max>1.5</position_i_max>
      <position_cmd_min>-240.0</position_cmd_min>
      <position_cmd_max>240.0</position_cmd_max>

      <joint_name>arm_3_joint</joint_name>
      <initial_position>0.0</initial_position>
      <position_p_gain>120.0</position_p_gain>
      <position_i_gain>0.09</position_i_gain>
      <position_d_gain>18.0</position_d_gain>
      <position_i_min>-1.3</position_i_min>
      <position_i_max>1.3</position_i_max>
      <position_cmd_min>-210.0</position_cmd_min>
      <position_cmd_max>210.0</position_cmd_max>

      <joint_name>arm_4_joint</joint_name>
      <initial_position>0.0</initial_position>
      <position_p_gain>70.0</position_p_gain>
      <position_i_gain>0.06</position_i_gain>
      <position_d_gain>9.0</position_d_gain>
      <position_i_min>-1.0</position_i_min>
      <position_i_max>1.0</position_i_max>
      <position_cmd_min>-120.0</position_cmd_min>
      <position_cmd_max>120.0</position_cmd_max>

      <joint_name>arm_5_joint</joint_name>
      <initial_position>0.0</initial_position>
      <position_p_gain>40.0</position_p_gain>
      <position_i_gain>0.05</position_i_gain>
      <position_d_gain>6.0</position_d_gain>
      <position_i_min>-0.8</position_i_min>
      <position_i_max>0.8</position_i_max>
      <position_cmd_min>-90.0</position_cmd_min>
      <position_cmd_max>90.0</position_cmd_max>

      <joint_name>arm_6_joint</joint_name>
      <initial_position>0.0</initial_position>
      <position_p_gain>35.0</position_p_gain>
      <position_i_gain>0.04</position_i_gain>
      <position_d_gain>5.0</position_d_gain>
      <position_i_min>-0.7</position_i_min>
      <position_i_max>0.7</position_i_max>
      <position_cmd_min>-80.0</position_cmd_min>
      <position_cmd_max>80.0</position_cmd_max>

      <joint_name>arm_7_joint</joint_name>
      <initial_position>0.0</initial_position>
      <position_p_gain>35.0</position_p_gain>
      <position_i_gain>0.04</position_i_gain>
      <position_d_gain>5.0</position_d_gain>
      <position_i_min>-0.7</position_i_min>
      <position_i_max>0.7</position_i_max>
      <position_cmd_min>-80.0</position_cmd_min>
      <position_cmd_max>80.0</position_cmd_max>

      <joint_name>head_1_joint</joint_name>
      <initial_position>0.0</initial_position>
      <position_p_gain>30.0</position_p_gain>
      <position_i_gain>0.03</position_i_gain>
      <position_d_gain>4.0</position_d_gain>
      <position_i_min>-0.5</position_i_min>
      <position_i_max>0.5</position_i_max>
      <position_cmd_min>-60.0</position_cmd_min>
      <position_cmd_max>60.0</position_cmd_max>

      <joint_name>head_2_joint</joint_name>
      <initial_position>0.0</initial_position>
      <position_p_gain>30.0</position_p_gain>
      <position_i_gain>0.03</position_i_gain>
      <position_d_gain>4.0</position_d_gain>
      <position_i_min>-0.5</position_i_min>
      <position_i_max>0.5</position_i_max>
      <position_cmd_min>-60.0</position_cmd_min>
      <position_cmd_max>60.0</position_cmd_max>
    </plugin>
  </model>
</sdf>
