<?xml version="1.0"?>
<sdf version="1.9">
  <model name="kuka_kr6r900sixx">
    <self_collide>false</self_collide>
    <allow_auto_disable>false</allow_auto_disable>

    <link name="base_link">
      <inertial>
        <pose>-0.0568 0 0.1304 0 0 0</pose>
        <mass>25.0</mass>
        <inertia>
          <ixx>0.32</ixx>
          <iyy>0.32</iyy>
          <izz>0.28</izz>
          <ixy>0.0</ixy>
          <ixz>0.0</ixz>
          <iyz>0.0</iyz>
        </inertia>
      </inertial>
      <visual name="base_link_visual">
        <geometry>
          <mesh>
            <uri>model://kuka_kr6r900sixx/meshes/converted_visual/base_link.stl</uri>
          </mesh>
        </geometry>
        <material>
          <ambient>0.18 0.18 0.18 1</ambient>
          <diffuse>0.18 0.18 0.18 1</diffuse>
        </material>
      </visual>
      <collision name="base_link_collision">
        <geometry>
          <mesh>
            <uri>model://kuka_kr6r900sixx/meshes/kr6_agilus/collision/base_link.stl</uri>
          </mesh>
        </geometry>
      </collision>
    </link>

    <link name="link_1">
      <pose relative_to="joint_a1">0 0 0 0 0 0</pose>
      <inertial>
        <pose>0.0116 -0.0010 -0.0483 0 0 0</pose>
        <mass>8.0</mass>
        <inertia>
          <ixx>0.07</ixx>
          <iyy>0.07</iyy>
          <izz>0.05</izz>
          <ixy>0.0</ixy>
          <ixz>0.0</ixz>
          <iyz>0.0</iyz>
        </inertia>
      </inertial>
      <visual name="link_1_visual">
        <geometry>
          <mesh>
            <uri>model://kuka_kr6r900sixx/meshes/converted_visual/link_1.stl</uri>
          </mesh>
        </geometry>
        <material>
          <ambient>0.93 0.45 0.10 1</ambient>
          <diffuse>0.93 0.45 0.10 1</diffuse>
        </material>
      </visual>
      <collision name="link_1_collision">
        <geometry>
          <mesh>
            <uri>model://kuka_kr6r900sixx/meshes/kr6_agilus/collision/link_1.stl</uri>
          </mesh>
        </geometry>
      </collision>
    </link>

    <link name="link_2">
      <pose relative_to="joint_a2">0 0 0 0 0 0</pose>
      <inertial>
        <pose>0.2277 -0.0050 0.0001 0 0 0</pose>
        <mass>6.0</mass>
        <inertia>
          <ixx>0.04</ixx>
          <iyy>0.04</iyy>
          <izz>0.03</izz>
          <ixy>0.0</ixy>
          <ixz>0.0</ixz>
          <iyz>0.0</iyz>
        </inertia>
      </inertial>
      <visual name="link_2_visual">
        <geometry>
          <mesh>
            <uri>model://kuka_kr6r900sixx/meshes/converted_visual/link_2.stl</uri>
          </mesh>
        </geometry>
        <material>
          <ambient>0.93 0.45 0.10 1</ambient>
          <diffuse>0.93 0.45 0.10 1</diffuse>
        </material>
      </visual>
      <collision name="link_2_collision">
        <geometry>
          <mesh>
            <uri>model://kuka_kr6r900sixx/meshes/kr6r900sixx/collision/link_2.stl</uri>
          </mesh>
        </geometry>
      </collision>
    </link>

    <link name="link_3">
      <pose relative_to="joint_a3">0 0 0 0 0 0</pose>
      <inertial>
        <pose>0.0203 0 0.0080 0 0 0</pose>
        <mass>4.0</mass>
        <inertia>
          <ixx>0.03</ixx>
          <iyy>0.03</iyy>
          <izz>0.02</izz>
          <ixy>0.0</ixy>
          <ixz>0.0</ixz>
          <iyz>0.0</iyz>
        </inertia>
      </inertial>
      <visual name="link_3_visual">
        <geometry>
          <mesh>
            <uri>model://kuka_kr6r900sixx/meshes/converted_visual/link_3.stl</uri>
          </mesh>
        </geometry>
        <material>
          <ambient>0.93 0.45 0.10 1</ambient>
          <diffuse>0.93 0.45 0.10 1</diffuse>
        </material>
      </visual>
      <collision name="link_3_collision">
        <geometry>
          <mesh>
            <uri>model://kuka_kr6r900sixx/meshes/kr6_agilus/collision/link_3.stl</uri>
          </mesh>
        </geometry>
      </collision>
    </link>

    <link name="link_4">
      <pose relative_to="joint_a4">0 0 0 0 0 0</pose>
      <inertial>
        <pose>0.2858 -0.0006 0.0092 0 0 0</pose>
        <mass>2.0</mass>
        <inertia>
          <ixx>0.015</ixx>
          <iyy>0.015</iyy>
          <izz>0.012</izz>
          <ixy>0.0</ixy>
          <ixz>0.0</ixz>
          <iyz>0.0</iyz>
        </inertia>
      </inertial>
      <visual name="link_4_visual">
        <geometry>
          <mesh>
            <uri>model://kuka_kr6r900sixx/meshes/converted_visual/link_4.stl</uri>
          </mesh>
        </geometry>
        <material>
          <ambient>0.93 0.45 0.10 1</ambient>
          <diffuse>0.93 0.45 0.10 1</diffuse>
        </material>
      </visual>
      <collision name="link_4_collision">
        <geometry>
          <mesh>
            <uri>model://kuka_kr6r900sixx/meshes/kr6r900sixx/collision/link_4.stl</uri>
          </mesh>
        </geometry>
      </collision>
    </link>

    <link name="link_5">
      <pose relative_to="joint_a5">0 0 0 0 0 0</pose>
      <inertial>
        <pose>0.0198 -0.0003 0 0 0 0</pose>
        <mass>1.6</mass>
        <inertia>
          <ixx>0.01</ixx>
          <iyy>0.01</iyy>
          <izz>0.008</izz>
          <ixy>0.0</ixy>
          <ixz>0.0</ixz>
          <iyz>0.0</iyz>
        </inertia>
      </inertial>
      <visual name="link_5_visual">
        <geometry>
          <mesh>
            <uri>model://kuka_kr6r900sixx/meshes/converted_visual/link_5.stl</uri>
          </mesh>
        </geometry>
        <material>
          <ambient>0.93 0.45 0.10 1</ambient>
          <diffuse>0.93 0.45 0.10 1</diffuse>
        </material>
      </visual>
      <collision name="link_5_collision">
        <geometry>
          <mesh>
            <uri>model://kuka_kr6r900sixx/meshes/kr6_agilus/collision/link_5.stl</uri>
          </mesh>
        </geometry>
      </collision>
    </link>

    <link name="link_6">
      <pose relative_to="joint_a6">0 0 0 0 0 0</pose>
      <inertial>
        <pose>-0.0068 0 0 0 0 0</pose>
        <mass>1.0</mass>
        <inertia>
          <ixx>0.005</ixx>
          <iyy>0.005</iyy>
          <izz>0.004</izz>
          <ixy>0.0</ixy>
          <ixz>0.0</ixz>
          <iyz>0.0</iyz>
        </inertia>
      </inertial>
      <visual name="link_6_visual">
        <geometry>
          <mesh>
            <uri>model://kuka_kr6r900sixx/meshes/converted_visual/link_6.stl</uri>
          </mesh>
        </geometry>
        <material>
          <ambient>0.18 0.18 0.18 1</ambient>
          <diffuse>0.18 0.18 0.18 1</diffuse>
        </material>
      </visual>
      <collision name="link_6_collision">
        <geometry>
          <mesh>
            <uri>model://kuka_kr6r900sixx/meshes/kr6_agilus/collision/link_6.stl</uri>
          </mesh>
        </geometry>
      </collision>
    </link>

    <link name="flange">
      <pose relative_to="joint_a6_flange">0 0 0 0 0 0</pose>
    </link>
    <link name="base">
      <pose relative_to="base_link_base">0 0 0 0 0 0</pose>
    </link>
    <link name="tool0">
      <pose relative_to="flange_tool0">0 0 0 0 0 0</pose>
    </link>

    <joint name="world_joint" type="fixed">
      <parent>world</parent>
      <child>base_link</child>
    </joint>

    <joint name="joint_a1" type="revolute">
      <parent>base_link</parent>
      <child>link_1</child>
      <pose relative_to="base_link">0 0 0.400 0 0 0</pose>
      <axis>
        <xyz>0 0 -1</xyz>
        <limit>
          <lower>-2.96706</lower>
          <upper>2.96706</upper>
          <effort>800</effort>
          <velocity>6.28319</velocity>
        </limit>
        <dynamics>
          <damping>0.6</damping>
          <friction>0.05</friction>
        </dynamics>
      </axis>
    </joint>

    <joint name="joint_a2" type="revolute">
      <parent>link_1</parent>
      <child>link_2</child>
      <pose relative_to="link_1">0.025 0 0 0 0 0</pose>
      <axis>
        <xyz>0 1 0</xyz>
        <limit>
          <lower>-3.31613</lower>
          <upper>0.7854</upper>
          <effort>900</effort>
          <velocity>5.23599</velocity>
        </limit>
        <dynamics>
          <damping>0.6</damping>
          <friction>0.05</friction>
        </dynamics>
      </axis>
    </joint>

    <joint name="joint_a3" type="revolute">
      <parent>link_2</parent>
      <child>link_3</child>
      <pose relative_to="link_2">0.455 0 0 0 0 0</pose>
      <axis>
        <xyz>0 1 0</xyz>
        <limit>
          <lower>-2.0944</lower>
          <upper>2.72271</upper>
          <effort>300</effort>
          <velocity>6.28319</velocity>
        </limit>
        <dynamics>
          <damping>1.0</damping>
          <friction>0.15</friction>
        </dynamics>
      </axis>
    </joint>

    <joint name="joint_a4" type="revolute">
      <parent>link_3</parent>
      <child>link_4</child>
      <pose relative_to="link_3">0 0 0.035 0 0 0</pose>
      <axis>
        <xyz>-1 0 0</xyz>
        <limit>
          <lower>-3.22886</lower>
          <upper>3.22886</upper>
          <effort>300</effort>
          <velocity>6.6497</velocity>
        </limit>
        <dynamics>
          <damping>0.8</damping>
          <friction>0.12</friction>
        </dynamics>
      </axis>
    </joint>

    <joint name="joint_a5" type="revolute">
      <parent>link_4</parent>
      <child>link_5</child>
      <pose relative_to="link_4">0.420 0 0 0 0 0</pose>
      <axis>
        <xyz>0 1 0</xyz>
        <limit>
          <lower>-2.0944</lower>
          <upper>2.0944</upper>
          <effort>250</effort>
          <velocity>6.77188</velocity>
        </limit>
        <dynamics>
          <damping>0.8</damping>
          <friction>0.10</friction>
        </dynamics>
      </axis>
    </joint>

    <joint name="joint_a6" type="revolute">
      <parent>link_5</parent>
      <child>link_6</child>
      <pose relative_to="link_5">0.080 0 0 0 0 0</pose>
      <axis>
        <xyz>-1 0 0</xyz>
        <limit>
          <lower>-6.10865</lower>
          <upper>6.10865</upper>
          <effort>200</effort>
          <velocity>10.73377</velocity>
        </limit>
        <dynamics>
          <damping>0.6</damping>
          <friction>0.08</friction>
        </dynamics>
      </axis>
    </joint>

    <joint name="joint_a6_flange" type="fixed">
      <parent>link_6</parent>
      <child>flange</child>
      <pose relative_to="link_6">0 0 0 0 0 0</pose>
    </joint>

    <joint name="base_link_base" type="fixed">
      <parent>base_link</parent>
      <child>base</child>
      <pose relative_to="base_link">0 0 0 0 0 0</pose>
    </joint>

    <joint name="flange_tool0" type="fixed">
      <parent>flange</parent>
      <child>tool0</child>
      <pose relative_to="flange">0 0 0 0 1.57079632679 0</pose>
    </joint>

    <plugin
      filename="gz-sim-joint-state-publisher-system"
      name="gz::sim::systems::JointStatePublisher">
      <joint_name>joint_a1</joint_name>
      <joint_name>joint_a2</joint_name>
      <joint_name>joint_a3</joint_name>
      <joint_name>joint_a4</joint_name>
      <joint_name>joint_a5</joint_name>
      <joint_name>joint_a6</joint_name>
    </plugin>

    <plugin
      filename="gz-sim-joint-trajectory-controller-system"
      name="gz::sim::systems::JointTrajectoryController">
      <joint_name>joint_a1</joint_name>
      <initial_position>1.5</initial_position>
      <position_p_gain>180.0</position_p_gain>
      <position_i_gain>0.12</position_i_gain>
      <position_d_gain>28.0</position_d_gain>
      <position_i_min>-2.0</position_i_min>
      <position_i_max>2.0</position_i_max>
      <position_cmd_min>-320.0</position_cmd_min>
      <position_cmd_max>320.0</position_cmd_max>

      <joint_name>joint_a2</joint_name>
      <initial_position>-1.57</initial_position>
      <position_p_gain>240.0</position_p_gain>
      <position_i_gain>0.16</position_i_gain>
      <position_d_gain>36.0</position_d_gain>
      <position_i_min>-2.5</position_i_min>
      <position_i_max>2.5</position_i_max>
      <position_cmd_min>-420.0</position_cmd_min>
      <position_cmd_max>420.0</position_cmd_max>

      <joint_name>joint_a3</joint_name>
      <initial_position>1.57</initial_position>
      <position_p_gain>55.0</position_p_gain>
      <position_i_gain>0.06</position_i_gain>
      <position_d_gain>9.0</position_d_gain>
      <position_i_min>-1.0</position_i_min>
      <position_i_max>1.0</position_i_max>
      <position_cmd_min>-110.0</position_cmd_min>
      <position_cmd_max>110.0</position_cmd_max>

      <joint_name>joint_a4</joint_name>
      <initial_position>0.0</initial_position>
      <position_p_gain>45.0</position_p_gain>
      <position_i_gain>0.05</position_i_gain>
      <position_d_gain>8.0</position_d_gain>
      <position_i_min>-0.8</position_i_min>
      <position_i_max>0.8</position_i_max>
      <position_cmd_min>-90.0</position_cmd_min>
      <position_cmd_max>90.0</position_cmd_max>

      <joint_name>joint_a5</joint_name>
      <initial_position>0.0</initial_position>
      <position_p_gain>35.0</position_p_gain>
      <position_i_gain>0.04</position_i_gain>
      <position_d_gain>6.5</position_d_gain>
      <position_i_min>-0.6</position_i_min>
      <position_i_max>0.6</position_i_max>
      <position_cmd_min>-70.0</position_cmd_min>
      <position_cmd_max>70.0</position_cmd_max>

      <joint_name>joint_a6</joint_name>
      <initial_position>0.0</initial_position>
      <position_p_gain>30.0</position_p_gain>
      <position_i_gain>0.03</position_i_gain>
      <position_d_gain>5.5</position_d_gain>
      <position_i_min>-0.5</position_i_min>
      <position_i_max>0.5</position_i_max>
      <position_cmd_min>-60.0</position_cmd_min>
      <position_cmd_max>60.0</position_cmd_max>
    </plugin>
  </model>
</sdf>
